
The following have been reloaded with a version change:
  1) python/.3.11.4 => python/3.11.4

INFO:root:Loading data...
INFO:root:Extracted GTF attributes: ['gene_id', 'gene_type', 'gene_name', 'level', 'mgi_id', 'havana_gene', 'transcript_id', 'transcript_type', 'transcript_name', 'transcript_support_level', 'tag', 'havana_transcript', 'exon_number', 'exon_id', 'protein_id', 'ccdsid', 'ont']
INFO:root:Extracted GTF attributes: ['transcript_id', 'gene_id', 'gene_name']
INFO:root:Mapping ORFs to gencode...
Empty DataFrame
Columns: [ID, pb_acc, misc, orf]
Index: []
  seqname  ...                     gene_name
0    chr1  ...                         10453
1    chr1  ...                         10453
2    chr1  ...  ENSMUSG00000033845.14_Mrpl15
3    chr1  ...  ENSMUSG00000033845.14_Mrpl15
4    chr1  ...  ENSMUSG00000033845.14_Mrpl15

[5 rows x 11 columns]
['gene' 'transcript' 'exon' 'CDS' 'start_codon' 'stop_codon' 'UTR'
 'Selenocysteine']
multiprocessing.pool.RemoteTraceback: 
"""
Traceback (most recent call last):
  File "/opt/conda/envs/lrpg/lib/python3.7/site-packages/pandas/core/indexes/base.py", line 3080, in get_loc
    return self._engine.get_loc(casted_key)
  File "pandas/_libs/index.pyx", line 70, in pandas._libs.index.IndexEngine.get_loc
  File "pandas/_libs/index.pyx", line 101, in pandas._libs.index.IndexEngine.get_loc
  File "pandas/_libs/hashtable_class_helper.pxi", line 4554, in pandas._libs.hashtable.PyObjectHashTable.get_item
  File "pandas/_libs/hashtable_class_helper.pxi", line 4562, in pandas._libs.hashtable.PyObjectHashTable.get_item
KeyError: 'orf_start'

The above exception was the direct cause of the following exception:

Traceback (most recent call last):
  File "/opt/conda/envs/lrpg/lib/python3.7/multiprocessing/pool.py", line 121, in worker
    result = (True, func(*args, **kwds))
  File "/opt/conda/envs/lrpg/lib/python3.7/multiprocessing/pool.py", line 47, in starmapstar
    return list(itertools.starmap(args[0], args[1]))
  File "00_scripts/05_mando_orf_calling.py", line 96, in plus_mapping_single_chromosome
    orf_exons = orf_exons[(orf_exons['prior_size'] <= orf_exons['orf_start']) &  (orf_exons['orf_start'] <= orf_exons['current_size'])]
  File "/opt/conda/envs/lrpg/lib/python3.7/site-packages/pandas/core/frame.py", line 3024, in __getitem__
    indexer = self.columns.get_loc(key)
  File "/opt/conda/envs/lrpg/lib/python3.7/site-packages/pandas/core/indexes/base.py", line 3082, in get_loc
    raise KeyError(key) from err
KeyError: 'orf_start'
"""

The above exception was the direct cause of the following exception:

Traceback (most recent call last):
  File "00_scripts/05_mando_orf_calling.py", line 298, in <module>
    main()
  File "00_scripts/05_mando_orf_calling.py", line 273, in main
    all_orfs = orf_mapping(orf_coord, gencode, sample_gtf, orf_seq, pool, results.num_cores)
  File "00_scripts/05_mando_orf_calling.py", line 82, in orf_mapping
    plus = plus_mapping(exons, orf_coord, start_codons, pool, num_cores)
  File "00_scripts/05_mando_orf_calling.py", line 126, in plus_mapping
    plus_orf_list = pool.starmap(plus_mapping_single_chromosome, iterable)
  File "/opt/conda/envs/lrpg/lib/python3.7/multiprocessing/pool.py", line 276, in starmap
    return self._map_async(func, iterable, starmapstar, chunksize).get()
  File "/opt/conda/envs/lrpg/lib/python3.7/multiprocessing/pool.py", line 657, in get
    raise self._value
KeyError: 'orf_start'
INFO:root:Loading data...
Traceback (most recent call last):
  File "00_scripts/05_orf_calling.py", line 307, in <module>
    main()
  File "00_scripts/05_orf_calling.py", line 267, in main
    orf_coord = read_orf(results.orf_coord)
  File "00_scripts/05_orf_calling.py", line 188, in read_orf
    orf[['pb_acc', 'misc', 'orf']] = orf['ID'].str.split('_', expand=True)
  File "/opt/conda/envs/lrpg/lib/python3.7/site-packages/pandas/core/frame.py", line 3160, in __setitem__
    self._setitem_array(key, value)
  File "/opt/conda/envs/lrpg/lib/python3.7/site-packages/pandas/core/frame.py", line 3186, in _setitem_array
    raise ValueError("Columns must be same length as key")
ValueError: Columns must be same length as key
